<?xml version="1.0" ?>
<robot name="zetabank" xmlns:xacro="http://ros.org/wiki/xacro">
  <xacro:include filename="$(find zetabank_description)/urdf/common_properties.xacro"/>
  <xacro:include filename="$(find zetabank_description)/urdf/zetabank.gazebo.xacro"/>
  <xacro:include filename="$(find zetabank_description)/urdf/sonar_sensor.urdf.xacro"/>
  
  <link name="base_footprint"/>

  <joint name="base_joint" type="fixed">
    <parent link="base_footprint"/>
    <child link="base_link" />
    <origin xyz="0 0 0.010" rpy="0 0 ${M_PI*0.5}"/>
  </joint>

  <link name="base_link">
    <visual>
      <origin xyz="-0 -0.33 0.0" rpy="0 0 0"/>
      <geometry>
        <mesh filename="package://zetabank_description/meshes/zetabank.STL" scale="1 1 1"/>
      </geometry>
      <material name="light_black"/>
    </visual>
    <collision>
      <origin xyz="0 0.064  0.048" rpy="0 0 ${M_PI*0.5}"/>
      <geometry>
        <box size="0.265 0.265 0.089"/>
      </geometry>
    </collision>
    <inertial>
      <origin xyz="0 0.064 0.048" rpy="0 0 ${M_PI*0.5}"/>
      <mass value="0.01"/>
      <inertia ixx="8.7002718e-03" ixy="-4.7576583e-05" ixz="1.1160499e-04" 
               iyy="8.6195418e-03" iyz="-3.5422299e-06" 
               izz="1.4612727e-02" /> 
    </inertial>

  </link>

<joint name="wheel_left_joint" type="continuous">
    <parent link="base_link"/>
    <child link="wheel_left_link"/>
    <origin xyz="0.180 0.0  0.080" rpy="${-M_PI*0.5} 0 ${-M_PI*0.5}"/>
    <axis xyz="0 0 1"/>
  </joint>

  <link name="wheel_left_link">    
    <collision>
      <origin rpy="0 0 0" xyz="0 0 0"/>
      <geometry>
        <cylinder length="0.050" radius="0.0812"/>
      </geometry>
    </collision>
    <inertial>
      <origin xyz="0 0 0" />
      <mass value="2.8498940e-02" />
      <inertia ixx="1.1175580e-05" ixy="-4.2369783e-11" ixz="-5.9381719e-09"
               iyy="1.1192413e-05" iyz="-1.4400107e-11"
               izz="2.0712558e-05" />
      </inertial>
  </link>

  <joint name="wheel_right_joint" type="continuous">
    <parent link="base_link"/>
    <child link="wheel_right_link"/>
    <origin xyz="-0.180 0.0  0.080" rpy="${-M_PI*0.5} 0 ${-M_PI*0.5}"/>
    <axis xyz="0 0 1"/>
  </joint>

  <link name="wheel_right_link">   
    <collision>
      <origin rpy="0 0 0" xyz="0 0 0"/>
      <geometry>
        <cylinder length="0.050" radius="0.0812"/>
      </geometry>
    </collision>
    <inertial>
      <origin xyz="0 0 0" />
      <mass value="2.8498940e-02" />
      <inertia ixx="1.1175580e-05" ixy="-4.2369783e-11" ixz="-5.9381719e-09"
               iyy="1.1192413e-05" iyz="-1.4400107e-11"
               izz="2.0712558e-05" />
      </inertial>
  </link>

  <joint name="caster_back_right_joint" type="fixed">
    <parent link="base_link"/>
    <child link="caster_back_right_link"/>
    <origin xyz="-0.177 0.264 -0.004" rpy="${-M_PI*0.5} 0 ${-M_PI*0.5}"/>
  </joint>

  <link name="caster_back_right_link">
    <collision>
      <origin xyz="0 0.001 0" rpy="0 0 0"/>
      <geometry>
        <box size="0.030 0.009 0.020"/>
      </geometry>
    </collision>

    <inertial>
      <origin xyz="0 0 0" />
      <mass value="0.005" />
      <inertia ixx="0.001" ixy="0.0" ixz="0.0"
               iyy="0.001" iyz="0.0"
               izz="0.001" />
    </inertial>
  </link>

  <joint name="caster_back_left_joint" type="fixed">
    <parent link="base_link"/>
    <child link="caster_back_left_link"/>
    <origin xyz="0.177 0.264 -0.004" rpy="${-M_PI*0.5} 0 ${-M_PI*0.5}"/>
  </joint>

  <link name="caster_back_left_link">
    <collision>
      <origin xyz="0 0.001 0" rpy="0 0 0"/>
      <geometry>
        <box size="0.030 0.009 0.020"/>
      </geometry>
    </collision>

    <inertial>
      <origin xyz="0 0 0" />
      <mass value="0.005" />
      <inertia ixx="0.001" ixy="0.0" ixz="0.0"
               iyy="0.001" iyz="0.0"
               izz="0.001" />
    </inertial>
  </link>


  <joint name="imu_joint" type="fixed">
    <parent link="base_link"/>
    <child link="imu_link"/>
    <origin xyz="0.0 -0.07 0.37" rpy="0 0 ${-M_PI*0.5}"/>
  </joint>

  <link name="imu_link"/>


  <joint name="lidar_joint" type="fixed">
    <parent link="base_link"/>
    <child link="lidar_link"/>
    <origin xyz="0 -0.28 0.21" rpy="0 0 ${-M_PI*0.5}"/>
  </joint>
  <link name="lidar_link"/>




<xacro:sonar_sensor name="sonar_f" parent="base_link" ros_topic="sonar_f" update_rate="50" min_range="0.1" max_range="0.5" field_of_view="${25*M_PI/180}" ray_count="3" visualize="false">
  <origin xyz="0 -0.28 0.260" rpy="0 0 ${-M_PI*0.5}"/>
</xacro:sonar_sensor>
<xacro:sonar_sensor name="sonar_fr" parent="base_link" ros_topic="sonar_fr" update_rate="50" min_range="0.1" max_range="0.5" field_of_view="${25*M_PI/180}" ray_count="3" visualize="false">
  <origin xyz="-0.19 -0.24 0.260" rpy="0 0 ${-M_PI*0.75}"/>
</xacro:sonar_sensor>
<xacro:sonar_sensor name="sonar_r" parent="base_link" ros_topic="sonar_r" update_rate="50" min_range="0.1" max_range="0.5" field_of_view="${25*M_PI/180}" ray_count="3" visualize="false">
  <origin xyz="-0.26 -0.07 0.260" rpy="0 0 ${-M_PI}"/>
</xacro:sonar_sensor>
<xacro:sonar_sensor name="sonar_br" parent="base_link" ros_topic="sonar_br" update_rate="50" min_range="0.1" max_range="0.5" field_of_view="${25*M_PI/180}" ray_count="3" visualize="false">
  <origin xyz="-0.2 0.3 0.22" rpy="0 0 ${M_PI*0.666}"/>
</xacro:sonar_sensor>
<xacro:sonar_sensor name="sonar_bl" parent="base_link" ros_topic="sonar_bl" update_rate="50" min_range="0.1" max_range="0.5" field_of_view="${25*M_PI/180}" ray_count="3" visualize="false">
  <origin xyz="0.2 0.3 0.22" rpy="0 0 ${M_PI*0.433}"/>
</xacro:sonar_sensor>
<xacro:sonar_sensor name="sonar_l" parent="base_link" ros_topic="sonar_l" update_rate="50" min_range="0.1" max_range="0.5" field_of_view="${25*M_PI/180}" ray_count="3" visualize="false">
  <origin xyz="0.26 -0.07 0.260" rpy="0 0 0"/>
</xacro:sonar_sensor>
<xacro:sonar_sensor name="sonar_fl" parent="base_link" ros_topic="sonar_fl" update_rate="50" min_range="0.1" max_range="0.5" field_of_view="${25*M_PI/180}" ray_count="3" visualize="false">
  <origin xyz="0.19 -0.24 0.260" rpy="0 0 ${-M_PI*0.25}"/>
</xacro:sonar_sensor>

</robot>
